Workbook

Sheet T00
A1: INDEX
A2: Cloud ERP – Steelstone IT | Master index of all form specification sheets | Jurisdiction: Pakistan
A4: Sr. No | B4: Page No | C4: Form / Document | D4: Module | E4: DUMMY ENTRIES
A5: 1 | B5: 01 | C5: ENTERPRISE REGISTRATION | D5: Operations | E5: 1
A6: 2 | B6: 02 | C6: MANUFACTURER (SUPPLIER) REGISTRATION | D6: Sales | E6: 3
A7: 3 | B7: 03 | C7: DISTRIBUTOR REGISTRATION | D7: Sales | E7: 5
A8: 4 | B8: 04 | C8: CUSTOMER REGISTRATION - END USER | D8: Sales | E8: 5
A9: 5 | B9: 05 | C9: TRANSPORTER REGISTRATION | D9: Operations | E9: 3
A10: 6 | B10: 06 | C10: VEHICLE REGISTRATION | D10: Operations | E10: 20
A11: 7 | B11: 07 | C11: MANPOWER / HR - EMPLOYEE REGISTRATION | D11: Operations | E11: 25
A12: 8 | B12: 08 | C12: BILL (SUPPLIER / VENDOR BILL BOOKING) | D12: Operations | E12: 150
A13: 9 | B13: 09 | C13: QUOTATION (SALES QUOTE) | D13: Sales | E13: 50
A14: 10 | B14: 10 | C14: PAYMENT VOUCHER | D14: Finance | E14: 75
A15: 11 | B15: 11 | C15: SALES TAX INVOICE | D15: Sales | E15: 40
A16: 12 | B16: 12 | C16: PAYROLL | D16: Operations | E16: 5
... A19: 15 | B19: 15 | C19: PAYMENT RECEIPT (CUSTOMER RECEIPT) | D19: Finance | E19: 60

Sheet T01
A1: SECTION 1 - BUSINESS REGISTRATION | E1: SECTION 2 - REGISTERED OFFICE & OTHER ADDRESSES | P1: SECTION 3 - POINTS OF CONTACT | S1: SECTION 4 - BANKING DETAILS - multiple options
A2: 1.1 Business name (Title) | B2: 1.2 Legal status | C2: 1.3 NTN / CNIC number | D2: 1.4 Filer status | E2: 2.1 Registered office - address line 1 | F2: 2.2 Registered office - address line 2 | G2: 2.3 City | H2: 2.4 District / Tehsil | I2: 2.5 Province / Territory | J2: 2.6 Country | K2: 2.7 Is the registered office the same as the main business address? | L2: 2.8 Correspondence / mailing address (if different) | M2: 2.9 Branch / factory / warehouse address(es) | N2: 2.10 Landline number | O2: 2.11 Geo-coordinates of main business address (lat, long) | P2: 3.1 Primary POC - full name | Q2: 3.2 Primary POC - designation | R2: 3.3 Primary POC - mobile | S2: 4.1 Bank name | T2: 4.2 Title of account | U2: 4.3 Account number
A3: Steelstone Building Materials (Pvt) Ltd | B3: Private Limited Company | C3: 4521789-3 | D3: Active Filer | E3: Office 12, 3rd Floor, Siddiq Trade Centre | F3: Main Boulevard, Gulberg III | G3: Lahore | H3: Lahore City | I3: Punjab | J3: Pakistan | K3: Yes | L3: Same as registered office | M3: Warehouse: Plot 45, Sundar Industrial Estate, Raiwind Road, Lahore | N3: 042-35781234 | O3: 31.5165, 74.3487 | P3: Usman Tariq | Q3: Chief Executive Officer | R3: 0300-4567812 | S3: Meezan Bank Ltd | T3: Steelstone Building Materials (Pvt) Ltd | U3: 0211-0104567890

Sheet T02
A1: SECTION 1 - BUSINESS REGISTRATION | E1: SECTION 2 - PLANTS / PRODUCTION FACILITIES | R1: SECTION 3 - POINTS OF CONTACT | U1: SECTION 4 - BANK ACCOUNT DETAILS | X1: SECTION 5 - WORKING CALENDAR, SHIFTS & DISPATCH WINDOWS | AK1: SECTION 6 - PRODUCT PRICING | AP1: SECTION 7 - WITHHOLDING TAX EXEMPTION
A2: 1.1 Business name (Title) | B2: 1.2 Legal status | C2: 1.3 NTN / CNIC number | D2: 1.4 Filer status | E2: 2.1 Plant serial no. | F2: 2.2 Plant name | G2: 2.3 Plant code | H2: 2.4 Plant address (full) | I2: 2.5 Plant city / province | J2: 2.6 Plant geo-coordinates (lat, long) | K2: 2.7 Plant Manager - full name & designation | L2: 2.8 Plant Manager - mobile | M2: 2.9 Production Manager - full name & designation | N2: 2.10 Production Manager - mobile | O2: 2.11 Plant landline / control room number | P2: 2.12 Products manufactured at this plant | Q2: 2.13 Plant operational status | R2: 3.1 Full name | S2: 3.2 Designation | T2: 3.3 Mobile number | U2: 4.1 Bank name | V2: 4.2 Title of account | W2: 4.3 Account number | X2: 5.1 Working days per week | Y2: 5.2 Weekly off day(s) | Z2: 5.3 Plant operating pattern | AA2: 5.4 Shift timings | AB2: 5.5 Dispatch / loading hours | AC2: 5.6 Order cut-off time for same-day dispatch | AD2: 5.7 Office / commercial working hours | AE2: 5.8 Annual maintenance shutdown period | AF2: 5.9 Public / religious holidays observed | AG2: 5.10 Ramadan / seasonal timing changes | AH2: 5.11 Emergency / after-hours dispatch available? | AI2: 5.12 Calendar applies to (plant) | AJ2: 5.13 Calendar effective from / to | AK2: 6.1 Name of product | AL2: 6.2 Unit of measure (UoM) | AM2: 6.3 Price per UoM (PKR) | AN2: 6.4 Discount | AO2: 6.5 Discount validity (from / to) | AP2: 7.1 Exemption availed? | AQ2: 7.2 Exemption validity (from / to) | AR2: 7.3 Withholding tax rate during exemption (%)
A3: Margalla Cement Ltd | B3: Public Limited Company (Listed) | C3: 0712345-6 | D3: Active Filer | E3: 1 | F3: Margalla Cement - Chakwal Plant | G3: MCL-CHK | H3: Kallar Kahar Road, Mouza Dhudial, Tehsil Choa Saidan Shah | I3: Chakwal / Punjab | J3: 32.7802, 72.8531 | K3: Engr. Kamran Haider - General Manager Plant | L3: 0333-5412780 | M3: Faisal Mehmood - Production Manager | N3: 0321-5098122 | O3: 0543-661200 | P3: OPC 53 (bag & bulk), SRC (bag & bulk) | Q3: Operational | R3: Shahid Iqbal | S3: Regional Sales Manager - Central Punjab | T3: 0300-8451290 | U3: Habib Bank Ltd | V3: Margalla Cement Ltd - Collection A/c | W3: 1234-79001122-03 | X3: 6 | Y3: Sunday | Z3: 24x7 continuous kiln; 3 shifts | AA3: A 06:00-14:00; B 14:00-22:00; C 22:00-06:00 | AB3: 07:00-23:00 | AC3: 0.58333333 | AD3: 09:00-17:30 (Mon-Sat) | AE3: 15-Jan to 05-Feb (kiln relining) | AF3: Eid-ul-Fitr (3 days), Eid-ul-Adha (3 days), 14-Aug, 9/10 Muharram | AG3: Ramadan dispatch 08:00-16:00 & 21:00-02:00 | AH3: Yes - with 12 hours notice | AI3: Margalla Cement - Chakwal Plant | AJ3: 01-Jan-2026 to 31-Dec-2026 | AK3: OPC Cement Grade 53 - 50 kg bag | AL3: Bag | AM3: 1290 | AN3: PKR 10 per bag on > 5,000 bags/month | AO3: 01-Jul-2026 to 31-Dec-2026 | AP3: No | AQ3: N/A | AR3: N/A
A4: Indus Valley Cement (Pvt) Ltd | B4: Private Limited Company | C4: 3398761-2 | D4: Active Filer | E4: 1 | F4: Indus Valley Cement - D.G. Khan Plant | G4: IVC-DGK | H4: Sakhi Sarwar Road, 22 km west of D.G. Khan | I4: Dera Ghazi Khan / Punjab | J4: 30.0512, 70.4471 | K4: Tariq Mahmood - Plant Head | L4: 0301-7745120 | M4: Adnan Qureshi - Production Manager | N4: 0345-6612398 | O4: 064-2461550 | P4: Slag, PPC, OPC jumbo, Rapid hardening | Q4: Operational | R4: Rizwan Akhtar | S4: Key Account Manager | T4: 0302-4418823 | U4: MCB Bank Ltd | V4: Indus Valley Cement (Pvt) Ltd | W4: 0876-5501234401 | X4: 6 | Y4: Sunday | Z4: 24x7 continuous kiln; 3 shifts | AA4: A 06:00-14:00; B 14:00-22:00; C 22:00-06:00 | AB4: 07:00-23:00 | AC4: 0.58333333 | AD4: 09:00-17:30 (Mon-Sat) | AE4: 15-Jan to 05-Feb (kiln relining) | AF4: Eid-ul-Fitr (3 days), Eid-ul-Adha (3 days), 14-Aug, 9/10 Muharram | AG4: Ramadan dispatch 08:00-16:00 & 21:00-02:00 | AH4: Yes - with 12 hours notice | AI4: Indus Valley Cement - D.G. Khan Plant | AJ4: 01-Jan-2026 to 31-Dec-2026 | AK4: Slag Cement - 50 kg bag | AL4: Bag | AM4: 1240 | AN4: 2% on advance payment | AO4: 01-Apr-2026 to 30-Sep-2026 | AP4: Yes | AQ4: 01-Jul-2025 to 30-Jun-2026 | AR4: 0.01
A5: Salt Range White Cement Ltd | B5: Public Limited Company (Unlisted) | C5: 2276540-9 | D5: Active Filer | E5: 1 | F5: Salt Range - Khewra White Cement Plant | G5: SRW-KHW | H5: Khewra-Pind Dadan Khan Road, Khewra | I5: Jhelum / Punjab | J5: 32.6479, 73.0105 | K5: Dr. Naveed Anjum - Plant Director | L5: 0300-5567431 | M5: Salman Javed - Production Manager | N5: 0331-2289014 | O5: 0544-211875 | P5: White cement, Low heat cement, OPC bag | Q5: Under maintenance | R5: Ayesha Siddiqui | S5: Sales Coordinator | T5: 0333-4290176 | U5: Bank Alfalah Ltd | V5: Salt Range White Cement Ltd | W5: 5501-1004-0098712 | X5: 6 | Y5: Sunday | Z5: Single shift (white cement mill) | AA5: 08:00-17:00 | AB5: 09:00-17:00 | AC5: 0.58333333 | AD5: 09:00-17:30 (Mon-Sat) | AE5: 01-Sep to 15-Oct-2026 (mill upgrade) | AF5: Eid-ul-Fitr (3 days), Eid-ul-Adha (3 days), 14-Aug, 9/10 Muharram | AG5: Ramadan dispatch 08:00-16:00 & 21:00-02:00 | AH5: Yes - with 12 hours notice | AI5: Salt Range - Khewra White Cement Plant | AJ5: 01-Jan-2026 to 31-Dec-2026 | AK5: White Cement - 40 kg bag | AL5: Bag | AM5: 2350 | AN5: None | AO5: N/A | AP5: No | AQ5: N/A | AR5: N/A

Sheet T03
A1: SECTION 1 - BUSINESS REGISTRATION | E1: SECTION 2 - POINTS OF CONTACT | H1: SECTION 3 - BANK ACCOUNT DETAILS | K1: SECTION 4 - PAYMENT TERMS
A2: 1.1 Business name (Title) | B2: 1.2 Legal status | C2: 1.3 NTN / CNIC number | D2: 1.4 Filer status | E2: 2.1 Full name | F2: 2.2 Designation | G2: 2.3 Mobile number | H2: 3.1 Bank name | I2: 3.2 Title of account | J2: 3.3 Account number | K2: 4.1 Payment terms | L2: 4.2 Early payment / prompt settlement discount
A3: Gujranwala Cement Traders | B3: Sole Proprietorship | C3: 34101-2567891-3 (CNIC) | D3: Active Filer | E3: Haji Muhammad Rafiq | F3: Proprietor | G3: 0300-6421785 | H3: Allied Bank Ltd | I3: Gujranwala Cement Traders | J3: 0010-0045678-9012 | K3: Credit 30 days | L3: 1% if paid within 7 days
A4: Sheikhupura Building Stores (AOP) | B4: Association of Persons (Partnership) | C4: 5123987-1 | D4: Active Filer | E4: Imran Bashir | F4: Managing Partner | G4: 0321-4150992 | H4: United Bank Ltd | I4: Sheikhupura Building Stores | J4: 0415-2280117 | K4: Credit 15 days | L4: 0.5% if paid within 5 days
A5: Kasur Construction Supplies | B5: Sole Proprietorship | C5: 35102-9087612-5 (CNIC) | D5: Inactive / Non-filer | E5: Nadeem Akram | F5: Proprietor | G5: 0345-7719034 | H5: Bank Al Habib Ltd | I5: Nadeem Akram | J5: 1002-0981-012233-01 | K5: Advance payment | L5: None
A6: Lyallpur Cement House (Pvt) Ltd | B6: Private Limited Company | C6: 4410982-6 | D6: Active Filer | E6: Zahid Hussain | F6: Director Sales | G6: 0300-7651123 | H6: Meezan Bank Ltd | I6: Lyallpur Cement House (Pvt) Ltd | J6: 0301-0100998877 | K6: Credit 30 days | L6: 1% if paid within 10 days
A7: Sahiwal Traders & Co (AOP) | B7: Association of Persons (Partnership) | C7: 6021345-8 | D7: Active Filer | E7: Asif Mehmood | F7: Partner | G7: 0333-6908812 | H7: Faysal Bank Ltd | I7: Sahiwal Traders & Co | J7: 3321-3010-0005566 | K7: Credit 7 days | L7: None

Sheet T04
A1: SECTION 1 - BUSINESS REGISTRATION | E1: SECTION 2 - DELIVERY MODE SELECTION | O1: SECTION 3 - BAG DELIVERY POINTS | AC1: SECTION 4 - BULKER DELIVERY POINTS | AG1: SECTION 5 - POINTS OF CONTACT | AJ1: SECTION 6 - BANK ACCOUNT DETAILS | AM1: SECTION 7 - EXEMPTION CERTIFICATES
A2: 1.1 Business name (Title) | B2: 1.2 Legal status | C2: 1.3 NTN / CNIC number | D2: 1.4 Filer status | E2: 2.1 Delivery mode required (DELIVERY-TYPE CHECK) | F2: 2.2 Number of bag delivery points | G2: 2.3 Number of bulker delivery points | H2: 2.4 Delivery basis / Incoterm | I2: 2.5 Transport arrangement | J2: 2.6 Preferred delivery days | K2: 2.7 Preferred delivery time window | L2: 2.8 Advance notice required before delivery (hours) | M2: 2.9 Site access constraints | N2: 2.10 Delivery documentation required at gate | O2: 3.1 Bag delivery point serial no. | P2: 3.2 Delivery point name / code | Q2: 3.3 Address line 1 | R2: 3.4 Address line 2 / landmark | S2: 3.5 City / District | T2: 3.6 Province | U2: 3.7 Geo-coordinates (lat, long) | V2: 3.8 Site contact - name & mobile | W2: 3.9 Receiving hours at this point | X2: 3.10 Covered storage available & capacity (bags) | Y2: 3.11 Unloading labour provided by | Z2: 3.12 Largest vehicle that can access the site | AA2: 3.13 Is this the default bag delivery point? | AB2: 3.14 Delivery point status | AC2: 4.1 Delivery point name | AD2: 4.2 Address | AE2: 4.3 POC name | AF2: 4.4 Mobile number | AG2: 5.1 Full name | AH2: 5.2 Designation | AI2: 5.3 Mobile number | AJ2: 6.1 Bank name | AK2: 6.2 Title of account | AL2: 6.3 Account number | AM2: 7.1 Certificate number | AN2: 7.2 Issuing authority / tax office | AO2: 7.3 Section / statutory reference | AP2: 7.4 Applicable tax type & normal rate | AQ2: 7.5 Exempted / reduced rate granted | AR2: 7.6 Valid from | AS2: 7.7 Valid until | AT2: 7.8 Renewal reminder lead time (days) | AU2: 7.9 Certificate copy attached | AV2: 7.10 Verified by & date (internal) | AW2: 7.11 Certificate status
A3: Bahria Heights Developers (Pvt) Ltd | B3: Private Limited Company | C3: 7712098-4 | D3: Active Filer | E3: Both (bag & bulker) | F3: 1 | G3: 1 | H3: Delivered at site (DAP) | I3: Arranged by Steelstone | J3: Mon-Sat | K3: 08:00-18:00 | L3: 24 | M3: Heavy vehicles allowed after 21:00 on main boulevard | N3: Delivery challan, weighbridge slip, gate pass | O3: 1 | P3: BHD-BAG-01 Tower Block C | Q3: Plot 7, Sector C, Bahria Heights | R3: Near Grand Mosque roundabout | S3: Lahore | T3: Punjab | U3: 31.3701, 74.1842 | V3: Waqas Ali - 0301-4412987 | W3: 08:00-18:00 | X3: Yes - 8,000 bags | Y3: Customer | Z3: 22-wheeler trailer | AA3: Yes | AB3: Active | AC3: BHD-BLK-01 Batching Plant | AD3: Batching plant, Sector F, Bahria Heights, Lahore | AE3: Engr. Hamza Rauf | AF3: 0322-4671203 | AG3: Faisal Rehman | AH3: Procurement Manager | AI3: 0300-4107765 | AJ3: Bank Alfalah Ltd | AK3: Bahria Heights Developers (Pvt) Ltd | AL3: 0099-1005-123987 | AM3: N/A | AN3: N/A | AO3: N/A | AP3: N/A | AQ3: N/A | AR3: N/A | AS3: N/A | AT3: N/A | AU3: No | AV3: N/A | AW3: Not applicable
A4: Crescent Builders & Contractors (AOP) | B4: Association of Persons (Partnership) | C4: 3087712-5 | D4: Active Filer | E4: Bag only | F4: 1 | G4: 0 | H4: Ex-warehouse (EXW) | I4: Customer's own transport | J4: Mon-Sat | K4: 09:00-17:00 | L4: 12 | M4: Narrow street - max 10-wheeler | N4: Delivery challan | O4: 1 | P4: CBC-BAG-01 Johar Town site | Q4: House 112, Block R-1, Johar Town | R4: Opp. Emporium Mall service lane | S4: Lahore | T4: Punjab | U4: 31.4677, 74.2663 | V4: Bilal Ahmad - 0333-4401298 | W4: 09:00-17:00 | X4: No | Y4: Steelstone | Z4: 10-wheeler truck | AA4: Yes | AB4: Active | AC4: N/A | AD4: N/A | AE4: N/A | AF4: N/A | AG4: Arshad Mahmood | AH4: Partner | AI4: 0321-8845120 | AJ4: Habib Bank Ltd | AK4: Crescent Builders & Contractors | AL4: 1478-79009876-01 | AM4: N/A | AN4: N/A | AO4: N/A | AP4: N/A | AQ4: N/A | AR4: N/A | AS4: N/A | AT4: N/A | AU4: No | AV4: N/A | AW4: Not applicable
A5: Punjab Highways Construction Co (Pvt) Ltd | B5: Private Limited Company | C5: 1190876-3 | D5: Active Filer | E5: Bulker only | F5: 0 | G5: 1 | H5: Delivered at site (DAP) | I5: Arranged by Steelstone | J5: All days | K5: 24 hours | L5: 48 | M5: Site on M-2 service road; escort needed | N5: Delivery challan, weighbridge slip, mill test certificate | O5: N/A | P5: N/A | Q5: N/A | R5: N/A | S5: N/A | T5: N/A | U5: N/A | V5: N/A | W5: N/A | X5: N/A | Y5: N/A | Z5: N/A | AA5: N/A | AB5: N/A | AC5: PHC-BLK-01 Sheikhupura Interchange camp | AD5: Km 28, Lahore-Sheikhupura Road, Camp Office | AE5: Engr. Saqib Nawaz | AF5: 0300-9412076 | AG5: Muhammad Ali Raza | AH5: Project Manager | AI5: 0345-4098213 | AJ5: National Bank of Pakistan | AK5: Punjab Highways Construction Co | AL5: 4012-3456-7890-12 | AM5: WHT-EX-2025/LTO-LHR/0457 | AN5: LTO Lahore | AO5: Sec. 159(1) Income Tax Ordinance 2001 | AP5: Income tax u/s 153(1)(a) - 5% | AQ5: 0.01 | AR5: 45839 | AS5: 46203 | AT5: 30 | AU5: Yes | AV5: Sana Iqbal - 05-Jul-2025 | AW5: Expired
A6: Ravi Riverfront Contractors (Pvt) Ltd | B6: Private Limited Company | C6: 8834521-0 | D6: Active Filer | E6: Both (bag & bulker) | F6: 1 | G6: 1 | H6: Delivered at site (DAP) | I6: Arranged by Steelstone | J6: Mon-Fri | K6: 07:00-19:00 | L6: 24 | M6: Security clearance at main gate | N6: Delivery challan, gate pass, MTC | O6: 1 | P6: RRC-BAG-01 Main store | Q6: Ravi City Phase 1, Store Yard 3 | R6: Near Shahdara flyover | S6: Lahore | T6: Punjab | U6: 31.6120, 74.2996 | V6: Usama Khalid - 0302-4455781 | W6: 07:00-19:00 | X6: Yes - 5,000 bags | Y6: Customer | Z6: 22-wheeler trailer | AA6: Yes | AB6: Active | AC6: RRC-BLK-01 Barrage batching plant | AD6: Ravi Barrage site, Phase 1, Lahore | AE6: Engr. Taimoor Aslam | AF6: 0331-4789021 | AG6: Sadia Noor | AH6: Head of Procurement | AI6: 0300-4981276 | AJ6: Standard Chartered Bank | AK6: Ravi Riverfront Contractors (Pvt) Ltd | AL6: 01-7654321-01 | AM6: WHT-EX-2026/RTO-LHR/1182 | AN6: RTO Lahore | AO6: Sec. 159(1) Income Tax Ordinance 2001 | AP6: Income tax u/s 153(1)(a) - 5% | AQ6: 0.02 | AR6: 46204 | AS6: 46568 | AT6: 30 | AU6: Yes | AV6: Sana Iqbal - 04-Jul-2026 | AW6: Valid
A7: Muhammad Aslam Construction | B7: Sole Proprietorship | C7: 35202-4412876-1 (CNIC) | D7: Active Filer | E7: Bag only | F7: 1 | G7: 0 | H7: Delivered at site (DAP) | I7: Arranged by Steelstone | J7: Mon-Sat | K7: 08:00-16:00 | L7: 12 | M7: None | N7: Delivery challan | O7: 1 | P7: MAC-BAG-01 DHA Phase 9 site | Q7: Plot 245, Block B, DHA Phase 9 Town | R7: Behind Commercial Area | S7: Lahore | T7: Punjab | U7: 31.4203, 74.4417 | V7: Muhammad Aslam - 0300-4219087 | W7: 08:00-16:00 | X7: Yes - 1,500 bags | Y7: Steelstone | Z7: 10-wheeler truck | AA7: Yes | AB7: Active | AC7: N/A | AD7: N/A | AE7: N/A | AF7: N/A | AG7: Muhammad Aslam | AH7: Proprietor | AI7: 0300-4219087 | AJ7: Askari Bank Ltd | AK7: Muhammad Aslam | AL7: 0512-0100334455 | AM7: N/A | AN7: N/A | AO7: N/A | AP7: N/A | AQ7: N/A | AR7: N/A | AS7: N/A | AT7: N/A | AU7: No | AV7: N/A | AW7: Not applicable

Sheet T05
A1: SECTION 1 - BUSINESS REGISTRATION | E1: SECTION 2 - POINTS OF CONTACT | H1: SECTION 3 - BANK ACCOUNT DETAILS | K1: SECTION 4 - WITHHOLDING TAX EXEMPTION
A2: 1.1 Business name (Title) | B2: 1.2 Legal status | C2: 1.3 NTN / CNIC number | D2: 1.4 Filer status | E2: 2.1 Full name | F2: 2.2 Designation | G2: 2.3 Mobile number | H2: 3.1 Bank name | I2: 3.2 Title of account | J2: 3.3 Account number | K2: 4.1 Exemption availed? | L2: 4.2 Exemption validity (from / to) | M2: 4.3 Withholding tax rate during exemption (%)
A3: Khan Goods Transport Co | B3: Sole Proprietorship | C3: 17301-5567812-9 (CNIC) | D3: Active Filer | E3: Gul Khan | F3: Owner | G3: 0300-5991287 | H3: Habib Bank Ltd | I3: Khan Goods Transport Co | J3: 2210-79004455-01 | K3: No | L3: N/A | M3: N/A
A4: Al-Madina Logistics (Pvt) Ltd | B4: Private Limited Company | C4: 5567123-4 | D4: Active Filer | E4: Tahir Mehmood | F4: Operations Manager | G4: 0321-4789012 | H4: MCB Bank Ltd | I4: Al-Madina Logistics (Pvt) Ltd | J4: 0654-7701122301 | K4: Yes | L4: 01-Jul-2026 to 30-Jun-2027 | M4: 0.02
A5: Punjab Bulk Carriers (AOP) | B5: Association of Persons (Partnership) | C5: 4098877-2 | D5: Inactive / Non-filer | E5: Sajjad Hussain | F5: Managing Partner | G5: 0333-4128876 | H5: United Bank Ltd | I5: Punjab Bulk Carriers | J5: 0900-2201456 | K5: No | L5: N/A | M5: N/A

Sheet T06
A1: SECTION 1 - VEHICLE IDENTIFICATION & REGISTRATION | Q1: SECTION 2 - VEHICLE STATUTORY DOCUMENTS & VALIDITY
A2: 1.1 Vehicle record code | B2: 1.2 Owning transporter | C2: 1.3 Ownership type | D2: 1.4 Registered owner name & NTN | E2: 1.5 Vehicle registration number | F2: 1.6 Registering authority & province | G2: 1.7 Date of registration | H2: 1.8 Registration book / smart card number | I2: 1.9 Vehicle category | J2: 1.10 Vehicle type | K2: 1.11 Make & model | L2: 1.12 Year of manufacture | M2: 1.13 Chassis number | N2: 1.14 Engine number | O2: 1.15 Colour | P2: 1.16 Registration status | Q2: 2.1 Route permit number | R2: 2.2 Route permit - valid until | S2: 2.3 Route permit - status (system-derived) | T2: 2.4 Fitness certificate number | U2: 2.5 Fitness certificate - valid until | V2: 2.6 Fitness certificate - status (system-derived) | W2: 2.7 Token tax - paid up to | X2: 2.8 Token tax - status (system-derived)
A3: VEH-001 | B3: TRN-001 - Khan Goods Transport Co | C3: Owned by transporter | D3: Khan Goods Transport Co / 17301-5567812-9 (CNIC) | E3: JLM-3574 | F3: Excise, Taxation & Narcotics Control Dept - Punjab | G3: 41934 | H3: PB-SC-5885652 | I3: Heavy transport vehicle (HTV) | J3: 22-wheeler trailer | K3: Hino 700 SH | L3: 2014 | M3: JH71606308K | N3: E13C-672323 | O3: Yellow | P3: Active | Q3: RTA-PB/31780/2014 | R3: 46467 | S3: =IF(R3<TODAY(),"Expired",IF(R3-TODAY()<=30,"Expiring soon","Valid")) -> Valid | T3: MVE-FC-436808 | U3: 46517 | V3: =IF(U3<TODAY(),"Expired",IF(U3-TODAY()<=30,"Expiring soon","Valid")) -> Valid | W3: 46568 | X3: =IF(W3<TODAY(),"Expired",IF(W3-TODAY()<=30,"Expiring soon","Valid")) -> Valid
A4: VEH-002 | B4: TRN-001 - Khan Goods Transport Co | C4: Owned by transporter | D4: Khan Goods Transport Co / 17301-5567812-9 (CNIC) | E4: FDA-1479 | F4: Excise, Taxation & Narcotics Control Dept - Punjab | G4: 44553 | H4: PB-SC-2105528 | I4: Heavy transport vehicle (HTV) | J4: 10-wheeler truck | K4: Hino 500 FM | L4: 2021 | M4: JH56174991K | N4: E13C-930851 | O4: Green | P4: Active | Q4: RTA-PB/67937/2021 | R4: 46644 | S4: =IF(R4<TODAY(),"Expired",IF(R4-TODAY()<=30,"Expiring soon","Valid")) -> Valid | T4: MVE-FC-619689 | U4: 46315 | V4: =IF(U4<TODAY(),"Expired",IF(U4-TODAY()<=30,"Expiring soon","Valid")) -> Expiring soon | W4: 46568 | X4: =IF(W4<TODAY(),"Expired",IF(W4-TODAY()<=30,"Expiring soon","Valid")) -> Valid
A5: VEH-003 | B5: TRN-001 - Khan Goods Transport Co | C5: Owned by transporter | D5: Khan Goods Transport Co / 17301-5567812-9 (CNIC) | E5: JLM-4312 | F5: Excise, Taxation & Narcotics Control Dept - Punjab | G5: 45021 | H5: PB-SC-3678756 | I5: Heavy transport vehicle (HTV) | J5: 10-wheeler truck | K5: Isuzu FVZ 34 | L5: 2023 | M5: JH48562297K | N5: E13C-365386 | O5: Yellow | P5: Active | Q5: RTA-PB/60163/2023 | R5: 46531 | S5: =IF(R5<TODAY(),"Expired",IF(R5-TODAY()<=30,"Expiring soon","Valid")) -> Valid | T5: MVE-FC-756344 | U5: 46280 | V5: =IF(U5<TODAY(),"Expired",IF(U5-TODAY()<=30,"Expiring soon","Valid")) -> Expired | W5: 46568 | X5: =IF(W5<TODAY(),"Expired",IF(W5-TODAY()<=30,"Expiring soon","Valid")) -> Valid
A6: VEH-004 | B6: TRN-001 - Khan Goods Transport Co | C6: Owned by transporter | D6: Khan Goods Transport Co / 17301-5567812-9 (CNIC) | E6: LES-3434 | F6: Excise, Taxation & Narcotics Control Dept - Punjab | G6: 44718 | H6: PB-SC-9180727 | I6: Light/medium goods vehicle (LTV) | J6: 6-wheeler truck | K6: Isuzu NPR | L6: 2022 | M6: JH14939185K | N6: E13C-428917 | O6: Red | P6: Active | Q6: RTA-PB/69797/2022 | R6: 46265 | S6: =IF(R6<TODAY(),"Expired",IF(R6-TODAY()<=30,"Expiring soon","Valid")) -> Expired | T6: MVE-FC-931913 | U6: 46553 | V6: =IF(U6<TODAY(),"Expired",IF(U6-TODAY()<=30,"Expiring soon","Valid")) -> Valid | W6: 46568 | X6: =IF(W6<TODAY(),"Expired",IF(W6-TODAY()<=30,"Expiring soon","Valid")) -> Valid
A7: VEH-005 | B7: TRN-001 - Khan Goods Transport Co | C7: Owned by transporter | D7: Khan Goods Transport Co / 17301-5567812-9 (CNIC) | E7: LEA-4610 | F7: Excise, Taxation & Narcotics Control Dept - Punjab | G7: 43664 | H7: PB-SC-3099075 | I7: Heavy transport vehicle (HTV) | J7: 22-wheeler trailer | K7: Hino 700 SH | L7: 2019 | M7: JH91584530K | N7: E13C-512053 | O7: Yellow | P7: Active | Q7: RTA-PB/67161/2019 | R7: 46488 | S7: =IF(R7<TODAY(),"Expired",IF(R7-TODAY()<=30,"Expiring soon","Valid")) -> Valid | T7: MVE-FC-670914 | U7: 46487 | V7: =IF(U7<TODAY(),"Expired",IF(U7-TODAY()<=30,"Expiring soon","Valid")) -> Valid | W7: 46203 | X7: =IF(W7<TODAY(),"Expired",IF(W7-TODAY()<=30,"Expiring soon","Valid")) -> Expired
A8: VEH-006 | B8: TRN-001 - Khan Goods Transport Co | C8: Attached (owner-driver) | D8: Owner-operator Munir Ahmad / 17301-5567812-9 (CNIC) | E8: MNB-7132 | F8: Excise, Taxation & Narcotics Control Dept - Punjab | G8: 43572 | H8: PB-SC-4155290 | I8: Heavy transport vehicle (HTV) | J8: 10-wheeler truck | K8: Hino 500 FM | L8: 2019 | M8: JH39753985K | N8: E13C-452288 | O8: Green | P8: Active | Q8: RTA-PB/88980/2019 | R8: 46307 | S8: =IF(R8<TODAY(),"Expired",IF(R8-TODAY()<=30,"Expiring soon","Valid")) -> Expiring soon | T8: MVE-FC-199966 | U8: 46642 | V8: =IF(U8<TODAY(),"Expired",IF(U8-TODAY()<=30,"Expiring soon","Valid")) -> Valid | W8: 46568 | X8: =IF(W8<TODAY(),"Expired",IF(W8-TODAY()<=30,"Expiring soon","Valid")) -> Valid
A9: VEH-007 | B9: TRN-001 - Khan Goods Transport Co | C9: Owned by transporter | D9: Khan Goods Transport Co / 17301-5567812-9 (CNIC) | E9: LES-4620 | F9: Excise, Taxation & Narcotics Control Dept - Punjab | G9: 44778 | H9: PB-SC-5113960 | I9: Heavy transport vehicle (HTV) | J9: 10-wheeler truck | K9: Isuzu FVZ 34 | L9: 2022 | M9: JH63362432K | N9: E13C-224015 | O9: Yellow | P9: Active | Q9: RTA-PB/89610/2022 | R9: 46421 | S9: =IF(R9<TODAY(),"Expired",IF(R9-TODAY()<=30,"Expiring soon","Valid")) -> Valid | T9: MVE-FC-901517 | U9: 46637 | V9: =IF(U9<TODAY(),"Expired",IF(U9-TODAY()<=30,"Expiring soon","Valid")) -> Valid | W9: 46568 | X9: =IF(W9<TODAY(),"Expired",IF(W9-TODAY()<=30,"Expiring soon","Valid")) -> Valid
A10: VEH-008 | B10: TRN-002 - Al-Madina Logistics (Pvt) Ltd | C10: Owned by transporter | D10: Al-Madina Logistics (Pvt) Ltd / 5567123-4 | E10: JLM-7774 | F10: Excise, Taxation & Narcotics Control Dept - Punjab | G10: 44579 | H10: PB-SC-3082386 | I10: Light/medium goods vehicle (LTV) | J10: 6-wheeler truck | K10: Isuzu NPR | L10: 2022 | M10: JH76703399K | N10: E13C-540424 | O10: Green | P10: Active | Q10: RTA-PB/31424/2022 | R10: 46478 | S10: =IF(R10<TODAY(),"Expired",IF(R10-TODAY()<=30,"Expiring soon","Valid")) -> Valid | T10: MVE-FC-893878 | U10: 46449 | V10: =IF(U10<TODAY(),"Expired",IF(U10-TODAY()<=30,"Expiring soon","Valid")) -> Valid | W10: 46568 | X10: =IF(W10<TODAY(),"Expired",IF(W10-TODAY()<=30,"Expiring soon","Valid")) -> Valid
A11: VEH-009 | B11: TRN-002 - Al-Madina Logistics (Pvt) Ltd | C11: Owned by transporter | D11: Al-Madina Logistics (Pvt) Ltd / 5567123-4 | E11: LEC-8959 | F11: Excise, Taxation & Narcotics Control Dept - Punjab | G11: 42395 | H11: PB-SC-6732391 | I11: Heavy transport vehicle (HTV) | J11: 22-wheeler trailer | K11: Hino 700 SH | L11: 2016 | M11: JH92990533K | N11: E13C-118897 | O11: Yellow | P11: Active | Q11: RTA-PB/26932/2016 | R11: 46432 | S11: =IF(R11<TODAY(),"Expired",IF(R11-TODAY()<=30,"Expiring soon","Valid")) -> Valid | T11: MVE-FC-971863 | U11: 46280 | V11: =IF(U11<TODAY(),"Expired",IF(U11-TODAY()<=30,"Expiring soon","Valid")) -> Expired | W11: 46568 | X11: =IF(W11<TODAY(),"Expired",IF(W11-TODAY()<=30,"Expiring soon","Valid")) -> Valid
A12: VEH-010 | B12: TRN-002 - Al-Madina Logistics (Pvt) Ltd | C12: Owned by transporter | D12: Al-Madina Logistics (Pvt) Ltd / 5567123-4 | E12: FDA-3369 | F12: Excise, Taxation & Narcotics Control Dept - Punjab | G12: 43648 | H12: PB-SC-7924811 | I12: Heavy transport vehicle (HTV) | J12: 10-wheeler truck | K12: Hino 500 FM | L12: 2019 | M12: JH73063263K | N12: E13C-742669 | O12: Blue | P12: Active | Q12: RTA-PB/12945/2019 | R12: 46452 | S12: =IF(R12<TODAY(),"Expired",IF(R12-TODAY()<=30,"Expiring soon","Valid")) -> Valid | T12: MVE-FC-199275 | U12: 46315 | V12: =IF(U12<TODAY(),"Expired",IF(U12-TODAY()<=30,"Expiring soon","Valid")) -> Expiring soon | W12: 46203 | X12: =IF(W12<TODAY(),"Expired",IF(W12-TODAY()<=30,"Expiring soon","Valid")) -> Expired
A13: VEH-011 | B13: TRN-002 - Al-Madina Logistics (Pvt) Ltd | C13: Owned by transporter | D13: Al-Madina Logistics (Pvt) Ltd / 5567123-4 | E13: LEA-7121 | F13: Excise, Taxation & Narcotics Control Dept - Punjab | G13: 45255 | H13: PB-SC-9934645 | I13: Heavy transport vehicle (HTV) | J13: 10-wheeler truck | K13: Isuzu FVZ 34 | L13: 2023 | M13: JH95886168K | N13: E13C-788396 | O13: Blue | P13: Active | Q13: RTA-PB/32339/2023 | R13: 46265 | S13: =IF(R13<TODAY(),"Expired",IF(R13-TODAY()<=30,"Expiring soon","Valid")) -> Expired | T13: MVE-FC-754899 | U13: 46632 | V13: =IF(U13<TODAY(),"Expired",IF(U13-TODAY()<=30,"Expiring soon","Valid")) -> Valid | W13: 46568 | X13: =IF(W13<TODAY(),"Expired",IF(W13-TODAY()<=30,"Expiring soon","Valid")) -> Valid
A14: VEH-012 | B14: TRN-002 - Al-Madina Logistics (Pvt) Ltd | C14: Attached (owner-driver) | D14: Owner-operator Shaukat Khan / 5567123-4 | E14: LEC-3089 | F14: Excise, Taxation & Narcotics Control Dept - Punjab | G14: 44814 | H14: PB-SC-7526792 | I14: Light/medium goods vehicle (LTV) | J14: 6-wheeler truck | K14: Isuzu NPR | L14: 2022 | M14: JH48047710K | N14: E13C-278763 | O14: Red | P14: Active | Q14: RTA-PB/98693/2022 | R14: 46532 | S14: =IF(R14<TODAY(),"Expired",IF(R14-TODAY()<=30,"Expiring soon","Valid")) -> Valid | T14: MVE-FC-994732 | U14: 46548 | V14: =IF(U14<TODAY(),"Expired",IF(U14-TODAY()<=30,"Expiring soon","Valid")) -> Valid | W14: 46568 | X14: =IF(W14<TODAY(),"Expired",IF(W14-TODAY()<=30,"Expiring soon","Valid")) -> Valid
... A22: VEH-020 | B22: TRN-003 - Punjab Bulk Carriers (AOP) | C22: Owned by transporter | D22: Punjab Bulk Carriers (AOP) / 4098877-2 | E22: TKR-6050 | F22: Excise, Taxation & Narcotics Control Dept - Punjab | G22: 43428 | H22: PB-SC-9894207 | I22: Heavy transport vehicle (HTV) | J22: Bulker 30 MT | K22: FAW J6P + bulker | L22: 2018 | M22: JH49425467K | N22: E13C-538350 | O22: Yellow | P22: Inactive | Q22: RTA-PB/97758/2018 | R22: 46649 | S22: =IF(R22<TODAY(),"Expired",IF(R22-TODAY()<=30,"Expiring soon","Valid")) -> Valid | T22: MVE-FC-421995 | U22: 46559 | V22: =IF(U22<TODAY(),"Expired",IF(U22-TODAY()<=30,"Expiring soon","Valid")) -> Valid | W22: 46203 | X22: =IF(W22<TODAY(),"Expired",IF(W22-TODAY()<=30,"Expiring soon","Valid")) -> Expired

Sheet T07
A1: SECTION 1 - EMPLOYEE IDENTIFICATION & PERSONAL DETAILS | M1: SECTION 2 - CONTACT, ADDRESS & NEXT OF KIN | V1: SECTION 3 - EMPLOYMENT & POSTING DETAILS | AE1: SECTION 4 - QUALIFICATION, EXPERIENCE & TRAINING | AL1: SECTION 5 - STATUTORY REGISTRATIONS & TAX | AR1: SECTION 6 - COMPENSATION & PAYROLL SETUP | AW1: SECTION 7 - BANK ACCOUNT DETAILS FOR SALARY | AZ1: SECTION 8 - LEAVE, ATTENDANCE & WORKING CALENDAR | BG1: SECTION 9 - DRIVER DETAILS - LICENCE, MEDICAL & STATUTORY VERIFICATION
A2: 1.1 Employee code | B2: 1.2 Registering enterprise / company | C2: 1.3 Employment category (GATING FIELD) | D2: 1.4 Full name | E2: 1.5 Passport number & nationality | F2: 1.6 Date of birth | G2: 1.7 Age (system-derived) | H2: 1.8 Gender | I2: 1.9 Marital status | J2: 1.10 Religion | K2: 1.11 Blood group | L2: 1.12 Photograph | M2: 2.1 Mobile number | N2: 2.2 Alternate mobile number | O2: 2.3 Present / residential address | P2: 2.4 Permanent address | Q2: 2.5 City / province of residence | R2: 2.6 Emergency contact - name & relation | S2: 2.7 Emergency contact - mobile number | T2: 2.8 Next of kin for benefits & gratuity | U2: 2.9 Dependants (name, relation, date of birth) | V2: 3.1 Date of joining | W2: 3.2 Designation / job title | X2: 3.3 Department / function | Y2: 3.4 Grade / pay scale | Z2: 3.5 Employment status | AA2: 3.6 Probation period (months) & confirmation due date | AB2: 3.7 Contract start date | AC2: 3.8 Contract end date | AD2: 3.9 Contract - status (system-derived) | AE2: 4.1 Highest qualification [Relevant Only] | AF2: 4.2 Degree / certification title & specialisation | AG2: 4.3 Institution & year of completion | AH2: 4.4 Professional licence / registration number | AI2: 4.5 Total years of prior experience | AJ2: 4.6 Previous employer(s) - name, designation & period | AK2: 4.7 Mandatory safety induction completed - date | AL2: 5.1 National Tax Number (NTN) of employee | AM2: 5.2 FBR filer status (Active Taxpayer List) | AN2: 5.3 EOBI registration number | AO2: 5.4 EOBI registration date | AP2: 5.5 Police verification / character certificate number | AQ2: 5.6 COMPLIANCE STATUS (system-derived) | AR2: 6.1 Gross monthly salary (PKR) | AS2: 6.2 Basic salary (PKR) | AT2: 6.3 House rent allowance (PKR) | AU2: 6.4 Income tax deduction method | AV2: 6.5 EOBI contribution - employee & employer share | AW2: 7.1 Bank name | AX2: 7.2 Title of account | AY2: 7.3 Account number | AZ2: 8.1 Annual (earned) leave entitlement - days | BA2: 8.2 Casual leave entitlement - days | BB2: 8.3 Sick leave entitlement - days | BC2: 8.4 Leave year basis | BD2: 8.5 Opening leave balance at registration | BE2: 8.6 Attendance capture method | BF2: 8.7 Overtime approval authority | BG2: 9.1 Is the employee a driver? (GATING FIELD) | BH2: 9.2 Driver dispatch code | BI2: 9.3 Driving licence number | BJ2: 9.4 Licence class / type | BK2: 9.5 Licence - valid until | BL2: 9.6 Licence - status (system-derived) | BM2: 9.7 Driver medical fitness certificate number | BN2: 9.8 Driver medical fitness - valid until | BO2: 9.9 Police verification - valid until | BP2: 9.10 Police verification - status (system-derived) | BQ2: 9.11 DRIVER COMPLIANCE STATUS (system-derived)
A3: EMP-001 | B3: Steelstone Building Materials (Pvt) Ltd | C3: Management | D3: Usman Tariq | E3: Pakistani - Passport DR7375417 | F3: 31317 | G3: =DATEDIF(F3,TODAY(),"Y") -> 41 | H3: Male | I3: Married | J3: Islam | K3: B- | L3: Attached (EMP-001.jpg) | M3: 0312-8186347 | N3: 0309-8201625 | O3: House 286, Street 22, Shadbagh, Lahore | P3: Same as present | Q3: Lahore / Punjab | R3: Nasreen - Mother | S3: 0328-3435246 | T3: Spouse / parent (as per emergency contact) | U3: 2 children - Ayesha (daughter, 2015), Hamza (son, 2018) | V3: 45577 | W3: Chief Executive Officer | X3: Management | Y3: M-1 | Z3: Confirmed | AA3: 3 months - confirmation due Q1 2025 | AB3: N/A | AC3: N/A | AD3: =IF(ISNUMBER(AC3),IF(AC3<TODAY(),"Expired",IF(AC3-TODAY()<=30,"Expiring soon","Active")),"Not applicable") -> Not applicable | AE3: Master's | AF3: MBA (Finance) | AG3: LUMS, 2008 | AH3: N/A | AI3: 17 | AJ3: Lucky Cement - Officer - 3 yrs | AK3: 45593 | AL3: 6301486-2 | AM3: Active (ATL) | AN3: EOBI-908956973 | AO3: 45593 | AP3: Verified - Jan-2024 | AQ3: =IF(AND(LEFT(AP3,8)="Verified",AN3<>"Pending"),"Compliant","Non-compliant") -> Compliant | AR3: 1200000 | AS3: =ROUND(AR3*0.6,0) -> 720000 | AT3: =ROUND(AS3*0.45,0) -> 324000 | AU3: Monthly withholding u/s 149 (annualised) | AV3: Employee 1% / Employer 5% of minimum wage | AW3: MCB Bank Ltd | AX3: Usman Tariq | AY3: 4041-71457664-08 | AZ3: 14 | BA3: 10 | BB3: 8 | BC3: Calendar year (Jan-Dec) | BD3: 4 | BE3: Biometric | BF3: Management head | BG3: No | BH3: N/A | BI3: N/A | BJ3: N/A | BK3: N/A | BL3: Not applicable | BM3: N/A | BN3: N/A | BO3: N/A | BP3: Not applicable | BQ3: Not applicable
A4: EMP-002 | B4: Steelstone Building Materials (Pvt) Ltd | C4: Staff | D4: Kashif Nadeem | E4: Pakistani - no passport | F4: 36164 | G4: =DATEDIF(F4,TODAY(),"Y") -> 27 | H4: Male | I4: Single | J4: Islam | K4: A+ | L4: Attached (EMP-002.jpg) | M4: 0338-2556786 | N4: N/A | O4: House 96, Street 29, Wapda Town, Lahore | P4: Same as present | Q4: Lahore / Punjab | R4: Rukhsana - Wife | S4: 0330-8307093 | T4: Spouse / parent (as per emergency contact) | U4: None | V4: 45582 | W4: General Manager Sales | X4: Sales | Y4: M-2 | Z4: Confirmed | AA4: 3 months - confirmation due Q1 2025 | AB4: N/A | AC4: N/A | AD4: =IF(ISNUMBER(AC4),IF(AC4<TODAY(),"Expired",IF(AC4-TODAY()<=30,"Expiring soon","Active")),"Not applicable") -> Not applicable | AE4: Master's | AF4: MBA (Marketing) | AG4: IBA Karachi, 2010 | AH4: N/A | AI4: 3 | AJ4: Fresh graduate | AK4: 45593 | AL4: 2152554-3 | AM4: Active (ATL) | AN4: EOBI-743336677 | AO4: 45593 | AP4: Verified - Mar-2024 | AQ4: =IF(AND(LEFT(AP4,8)="Verified",AN4<>"Pending"),"Compliant","Non-compliant") -> Compliant | AR4: 650000 | AS4: =ROUND(AR4*0.6,0) -> 390000 | AT4: =ROUND(AS4*0.45,0) -> 175500 | AU4: Monthly withholding u/s 149 (annualised) | AV4: Employee 1% / Employer 5% of minimum wage | AW4: MCB Bank Ltd | AX4: Kashif Nadeem | AY4: 5930-62937464-07 | AZ4: 14 | BA4: 10 | BB4: 8 | BC4: Calendar year (Jan-Dec) | BD4: 10 | BE4: Biometric | BF4: Sales head | BG4: No | BH4: N/A | BI4: N/A | BJ4: N/A | BK4: N/A | BL4: Not applicable | BM4: N/A | BN4: N/A | BO4: N/A | BP4: Not applicable | BQ4: Not applicable
A5: EMP-003 | B5: Steelstone Building Materials (Pvt) Ltd | C5: Staff | D5: Sana Iqbal | E5: Pakistani - no passport | F5: 33271 | G5: =DATEDIF(F5,TODAY(),"Y") -> 35 | H5: Female | I5: Married | J5: Islam | K5: AB+ | L5: Attached (EMP-003.jpg) | M5: 0315-3258285 | N5: N/A | O5: House 101, Street 19, Wapda Town, Lahore | P5: Village Dhok Ratta, Okara | Q5: Mardan / KP | R5: Imran - Husband | S5: 0334-8127740 | T5: Spouse / parent (as per emergency contact) | U5: 2 children - Ayesha (daughter, 2015), Fatima (daughter, 2019) | V5: 45629 | W5: Finance Manager | X5: Finance | Y5: M-3 | Z5: Confirmed | AA5: 3 months - confirmation due Q1 2025 | AB5: N/A | AC5: N/A | AD5: =IF(ISNUMBER(AC5),IF(AC5<TODAY(),"Expired",IF(AC5-TODAY()<=30,"Expiring soon","Active")),"Not applicable") -> Not applicable | AE5: Professional | AF5: ACA (ICAP) | AG5: ICAP, 2014 | AH5: ICAP Member No. 11245 | AI5: 11 | AJ5: Fresh graduate | AK5: 45654 | AL5: 5507669-8 | AM5: Active (ATL) | AN5: EOBI-482440629 | AO5: 45654 | AP5: Verified - May-2024 | AQ5: =IF(AND(LEFT(AP5,8)="Verified",AN5<>"Pending"),"Compliant","Non-compliant") -> Compliant | AR5: 450000 | AS5: =ROUND(AR5*0.6,0) -> 270000 | AT5: =ROUND(AS5*0.45,0) -> 121500 | AU5: Monthly withholding u/s 149 (annualised) | AV5: Employee 1% / Employer 5% of minimum wage | AW5: MCB Bank Ltd | AX5: Sana Iqbal | AY5: 8115-75441881-09 | AZ5: 14 | BA5: 10 | BB5: 8 | BC5: Calendar year (Jan-Dec) | BD5: 11 | BE5: Biometric | BF5: Finance head | BG5: No | BH5: N/A | BI5: N/A | BJ5: N/A | BK5: N/A | BL5: Not applicable | BM5: N/A | BN5: N/A | BO5: N/A | BP5: Not applicable | BQ5: Not applicable
A6: EMP-004 | B6: Steelstone Building Materials (Pvt) Ltd | C6: Staff | D6: Hassan Raza | E6: Pakistani - Passport AB2127181 | F6: 34695 | G6: =DATEDIF(F6,TODAY(),"Y") -> 31 | H6: Male | I6: Single | J6: Islam | K6: A+ | L6: Attached (EMP-004.jpg) | M6: 0319-8827786 | N6: N/A | O6: House 431, Street 9, Township, Lahore | P6: Same as present | Q6: Lahore / Punjab | R6: Rukhsana - Wife | S6: 0321-3907974 | T6: Spouse / parent (as per emergency contact) | U6: None | V6: 45579 | W6: Accountant | X6: Finance | Y6: S-2 | Z6: Confirmed | AA6: 3 months - confirmation due Q1 2025 | AB6: N/A | AC6: N/A | AD6: =IF(ISNUMBER(AC6),IF(AC6<TODAY(),"Expired",IF(AC6-TODAY()<=30,"Expiring soon","Active")),"Not applicable") -> Not applicable | AE6: Bachelor's | AF6: B.Com (Hons) | AG6: Hailey College, 2016 | AH6: N/A | AI6: 8 | AJ6: Lucky Cement - Officer - 3 yrs | AK6: 45593 | AL6: 1494817-0 | AM6: Active (ATL) | AN6: EOBI-184159363 | AO6: 45593 | AP6: Verified - Aug-2024 | AQ6: =IF(AND(LEFT(AP6,8)="Verified",AN6<>"Pending"),"Compliant","Non-compliant") -> Compliant | AR6: 180000 | AS6: =ROUND(AR6*0.6,0) -> 108000 | AT6: =ROUND(AS6*0.45,0) -> 48600 | AU6: Monthly withholding u/s 149 (annualised) | AV6: Employee 1% / Employer 5% of minimum wage | AW6: Habib Bank Ltd | AX6: Hassan Raza | AY6: 5211-82734308-07 | AZ6: 14 | BA6: 10 | BB6: 8 | BC6: Calendar year (Jan-Dec) | BD6: 8 | BE6: Biometric | BF6: Finance head | BG6: No | BH6: N/A | BI6: N/A | BJ6: N/A | BK6: N/A | BL6: Not applicable | BM6: N/A | BN6: N/A | BO6: N/A | BP6: Not applicable | BQ6: Not applicable
A7: EMP-005 | B7: Steelstone Building Materials (Pvt) Ltd | C7: Staff | D7: Mariam Khalid | E7: Pakistani - no passport | F7: 31652 | G7: =DATEDIF(F7,TODAY(),"Y") -> 40 | H7: Female | I7: Married | J7: Islam | K7: B- | L7: Attached (EMP-005.jpg) | M7: 0347-6430310 | N7: 0341-1588893 | O7: House 327, Street 20, Shadbagh, Lahore | P7: Same as present | Q7: Lahore / Punjab | R7: Asad - Husband | S7: 0314-2097256 | T7: Spouse / parent (as per emergency contact) | U7: 2 children - Ahmed (son, 2012), Hamza (son, 2018) | V7: 45636 | W7: Accounts Officer | X7: Finance | Y7: S-3 | Z7: Confirmed | AA7: 3 months - confirmation due Q1 2025 | AB7: N/A | AC7: N/A | AD7: =IF(ISNUMBER(AC7),IF(AC7<TODAY(),"Expired",IF(AC7-TODAY()<=30,"Expiring soon","Active")),"Not applicable") -> Not applicable | AE7: Bachelor's | AF7: BBA (Accounting) | AG7: UCP Lahore, 2020 | AH7: N/A | AI7: 16 | AJ7: Maple Leaf Cement - Executive - 4 yrs | AK7: 45654 | AL7: Not registered | AM7: Non-filer | AN7: EOBI-280119945 | AO7: 45654 | AP7: Verified - Nov-2024 | AQ7: =IF(AND(LEFT(AP7,8)="Verified",AN7<>"Pending"),"Compliant","Non-compliant") -> Compliant | AR7: 120000 | AS7: =ROUND(AR7*0.6,0) -> 72000 | AT7: =ROUND(AS7*0.45,0) -> 32400 | AU7: Monthly withholding u/s 149 (annualised) | AV7: Employee 1% / Employer 5% of minimum wage | AW7: Habib Bank Ltd | AX7: Mariam Khalid | AY7: 2128-14696266-01 | AZ7: 14 | BA7: 10 | BB7: 8 | BC7: Calendar year (Jan-Dec) | BD7: 11 | BE7: Biometric | BF7: Finance head | BG7: No | BH7: N/A | BI7: N/A | BJ7: N/A | BK7: N/A | BL7: Not applicable | BM7: N/A | BN7: N/A | BO7: N/A | BP7: Not applicable | BQ7: Not applicable
A8: EMP-006 | B8: Steelstone Building Materials (Pvt) Ltd | C8: Staff | D8: Abdul Rehman | E8: Pakistani - no passport | F8: 29137 | G8: =DATEDIF(F8,TODAY(),"Y") -> 46 | H8: Male | I8: Married | J8: Islam | K8: O+ | L8: Attached (EMP-006.jpg) | M8: 0347-1104417 | N8: N/A | O8: House 448, Street 7, Wapda Town, Lahore | P8: Village Mouza Kot, Okara | Q8: Lahore / Punjab | R8: Shazia - Mother | S8: 0318-8321405 | T8: Spouse / parent (as per emergency contact) | U8: 2 children - Ahmed (son, 2012), Hamza (son, 2018) | V8: 45635 | W8: Cashier | X8: Finance | Y8: S-4 | Z8: Confirmed | AA8: 3 months - confirmation due Q1 2025 | AB8: N/A | AC8: N/A | AD8: =IF(ISNUMBER(AC8),IF(AC8<TODAY(),"Expired",IF(AC8-TODAY()<=30,"Expiring soon","Active")),"Not applicable") -> Not applicable | AE8: Intermediate | AF8: I.Com | AG8: Govt College Lahore, 2012 | AH8: N/A | AI8: 23 | AJ8: Maple Leaf Cement - Executive - 4 yrs | AK8: 45654 | AL8: 8933767-8 | AM8: Active (ATL) | AN8: EOBI-710379522 | AO8: 45654 | AP8: Verified - Jan-2024 | AQ8: =IF(AND(LEFT(AP8,8)="Verified",AN8<>"Pending"),"Compliant","Non-compliant") -> Compliant | AR8: 85000 | AS8: =ROUND(AR8*0.6,0) -> 51000 | AT8: =ROUND(AS8*0.45,0) -> 22950 | AU8: Monthly withholding u/s 149 (below taxable limit) | AV8: Employee 1% / Employer 5% of minimum wage | AW8: Habib Bank Ltd | AX8: Abdul Rehman | AY8: 8800-83778971-08 | AZ8: 14 | BA8: 10 | BB8: 8 | BC8: Calendar year (Jan-Dec) | BD8: 10 | BE8: Biometric | BF8: Finance head | BG8: No | BH8: N/A | BI8: N/A | BJ8: N/A | BK8: N/A | BL8: Not applicable | BM8: N/A | BN8: N/A | BO8: N/A | BP8: Not applicable | BQ8: Not applicable
A9: EMP-007 | B9: Steelstone Building Materials (Pvt) Ltd | C9: Staff | D9: Omer Farooq | E9: Pakistani - Passport BK7408931 | F9: 34084 | G9: =DATEDIF(F9,TODAY(),"Y") -> 33 | H9: Male | I9: Married | J9: Islam | K9: A+ | L9: Attached (EMP-007.jpg) | M9: 0346-8343975 | N9: N/A | O9: House 211, Street 24, Bund Road, Lahore | P9: Same as present | Q9: Lahore / Punjab | R9: Rukhsana - Wife | S9: 0300-6197912 | T9: Spouse / parent (as per emergency contact) | U9: 2 children - Ayesha (daughter, 2015), Fatima (daughter, 2019) | V9: 45650 | W9: Sales Manager | X9: Sales | Y9: M-3 | Z9: Confirmed | AA9: 3 months - confirmation due Q1 2025 | AB9: N/A | AC9: N/A | AD9: =IF(ISNUMBER(AC9),IF(AC9<TODAY(),"Expired",IF(AC9-TODAY()<=30,"Expiring soon","Active")),"Not applicable") -> Not applicable | AE9: Bachelor's | AF9: BBA (Marketing) | AG9: PU Lahore, 2011 | AH9: N/A | AI9: 9 | AJ9: Fresh graduate | AK9: 45654 | AL9: 8320810-2 | AM9: Active (ATL) | AN9: EOBI-606224414 | AO9: 45654 | AP9: Verified - Mar-2024 | AQ9: =IF(AND(LEFT(AP9,8)="Verified",AN9<>"Pending"),"Compliant","Non-compliant") -> Compliant | AR9: 300000 | AS9: =ROUND(AR9*0.6,0) -> 180000 | AT9: =ROUND(AS9*0.45,0) -> 81000 | AU9: Monthly withholding u/s 149 (annualised) | AV9: Employee 1% / Employer 5% of minimum wage | AW9: Habib Bank Ltd | AX9: Omer Farooq | AY9: 4474-58439197-07 | AZ9: 14 | BA9: 10 | BB9: 8 | BC9: Calendar year (Jan-Dec) | BD9: 8 | BE9: Biometric | BF9: Sales head | BG9: No | BH9: N/A | BI9: N/A | BJ9: N/A | BK9: N/A | BL9: Not applicable | BM9: N/A | BN9: N/A | BO9: N/A | BP9: Not applicable | BQ9: Not applicable
A10: EMP-008 | B10: Steelstone Building Materials (Pvt) Ltd | C10: Staff | D10: Ali Hamza | E10: Pakistani - no passport | F10: 32587 | G10: =DATEDIF(F10,TODAY(),"Y") -> 37 | H10: Male | I10: Married | J10: Islam | K10: B- | L10: Attached (EMP-008.jpg) | M10: 0312-6526028 | N10: N/A | O10: House 249, Street 29, Shadbagh, Lahore | P10: Same as present | Q10: Lahore / Punjab | R10: Rukhsana - Mother | S10: 0326-6139730 | T10: Spouse / parent (as per emergency contact) | U10: 2 children - Ahmed (son, 2012), Hamza (son, 2018) | V10: 45781 | W10: Sales Officer | X10: Sales | Y10: S-3 | Z10: Confirmed | AA10: 3 months - confirmation due within 2025 | AB10: N/A | AC10: N/A | AD10: =IF(ISNUMBER(AC10),IF(AC10<TODAY(),"Expired",IF(AC10-TODAY()<=30,"Expiring soon","Active")),"Not applicable") -> Not applicable | AE10: Bachelor's | AF10: BBA | AG10: Superior University, 2019 | AH10: N/A | AI10: 13 | AJ10: Maple Leaf Cement - Executive - 4 yrs | AK10: 45805 | AL10: 6705591-8 | AM10: Active (ATL) | AN10: EOBI-679690030 | AO10: 45805 | AP10: Verified - May-2025 | AQ10: =IF(AND(LEFT(AP10,8)="Verified",AN10<>"Pending"),"Compliant","Non-compliant") -> Compliant | AR10: 110000 | AS10: =ROUND(AR10*0.6,0) -> 66000 | AT10: =ROUND(AS10*0.45,0) -> 29700 | AU10: Monthly withholding u/s 149 (annualised) | AV10: Employee 1% / Employer 5% of minimum wage | AW10: Habib Bank Ltd | AX10: Ali Hamza | AY10: 4125-45835741-02 | AZ10: 14 | BA10: 10 | BB10: 8 | BC10: Calendar year (Jan-Dec) | BD10: 1 | BE10: Biometric | BF10: Sales head | BG10: No | BH10: N/A | BI10: N/A | BJ10: N/A | BK10: N/A | BL10: Not applicable | BM10: N/A | BN10: N/A | BO10: N/A | BP10: Not applicable | BQ10: Not applicable
A11: EMP-009 | B11: Steelstone Building Materials (Pvt) Ltd | C11: Staff | D11: Zeeshan Anwar | E11: Pakistani - no passport | F11: 32266 | G11: =DATEDIF(F11,TODAY(),"Y") -> 38 | H11: Male | I11: Married | J11: Islam | K11: AB+ | L11: Attached (EMP-009.jpg) | M11: 0324-1895791 | N11: 0342-3730534 | O11: House 55, Street 7, Shadbagh, Lahore | P11: Village Chak 45, Mardan | Q11: Sheikhupura / Punjab | R11: Shazia - Mother | S11: 0328-7159283 | T11: Spouse / parent (as per emergency contact) | U11: 2 children - Ahmed (son, 2012), Fatima (daughter, 2019) | V11: 45586 | W11: Sales Officer | X11: Sales | Y11: S-3 | Z11: Contract | AA11: 3 months - confirmation due Q1 2025 | AB11: 45566 | AC11: 46568 | AD11: =IF(ISNUMBER(AC11),IF(AC11<TODAY(),"Expired",IF(AC11-TODAY()<=30,"Expiring soon","Active")),"Not applicable") -> Active | AE11: Bachelor's | AF11: B.Sc Civil Technology | AG11: UET Lahore, 2021 | AH11: N/A | AI11: 14 | AJ11: DG Khan Cement - Officer - 2 yrs | AK11: 45593 | AL11: 9705099-2 | AM11: Active (ATL) | AN11: EOBI-995343231 | AO11: 45593 | AP11: Verified - Aug-2024 | AQ11: =IF(AND(LEFT(AP11,8)="Verified",AN11<>"Pending"),"Compliant","Non-compliant") -> Compliant | AR11: 110000 | AS11: =ROUND(AR11*0.6,0) -> 66000 | AT11: =ROUND(AS11*0.45,0) -> 29700 | AU11: Monthly withholding u/s 149 (annualised) | AV11: Employee 1% / Employer 5% of minimum wage | AW11: Meezan Bank Ltd | AX11: Zeeshan Anwar | AY11: 1928-37694832-08 | AZ11: 14 | BA11: 10 | BB11: 8 | BC11: Calendar year (Jan-Dec) | BD11: 11 | BE11: Biometric | BF11: Sales head | BG11: No | BH11: N/A | BI11: N/A | BJ11: N/A | BK11: N/A | BL11: Not applicable | BM11: N/A | BN11: N/A | BO11: N/A | BP11: Not applicable | BQ11: Not applicable
A12: EMP-010 | B12: Steelstone Building Materials (Pvt) Ltd | C12: Staff | D12: Naeem Akhtar | E12: Pakistani - Passport AB5811268 | F12: 33152 | G12: =DATEDIF(F12,TODAY(),"Y") -> 35 | H12: Male | I12: Married | J12: Islam | K12: B- | L12: Attached (EMP-010.jpg) | M12: 0335-9559454 | N12: N/A | O12: House 138, Street 1, Bund Road, Lahore | P12: Same as present | Q12: Lahore / Punjab | R12: Nasreen - Mother | S12: 0336-1409493 | T12: Spouse / parent (as per emergency contact) | U12: 2 children - Ayesha (daughter, 2015), Fatima (daughter, 2019) | V12: 45924 | W12: Logistics Manager | X12: Logistics | Y12: M-3 | Z12: Confirmed | AA12: 3 months - confirmation due within 2025 | AB12: N/A | AC12: N/A | AD12: =IF(ISNUMBER(AC12),IF(AC12<TODAY(),"Expired",IF(AC12-TODAY()<=30,"Expiring soon","Active")),"Not applicable") -> Not applicable | AE12: Master's | AF12: MS Supply Chain | AG12: NUST, 2013 | AH12: N/A | AI12: 12 | AJ12: DG Khan Cement - Officer - 2 yrs | AK12: 45928 | AL12: Not registered | AM12: Non-filer | AN12: EOBI-610334771 | AO12: 45928 | AP12: Verified - Nov-2025 | AQ12: =IF(AND(LEFT(AP12,8)="Verified",AN12<>"Pending"),"Compliant","Non-compliant") -> Compliant | AR12: 250000 | AS12: =ROUND(AR12*0.6,0) -> 150000 | AT12: =ROUND(AS12*0.45,0) -> 67500 | AU12: Monthly withholding u/s 149 (annualised) | AV12: Employee 1% / Employer 5% of minimum wage | AW12: Meezan Bank Ltd | AX12: Naeem Akhtar | AY12: 6670-61072145-04 | AZ12: 14 | BA12: 10 | BB12: 8 | BC12: Calendar year (Jan-Dec) | BD12: 0 | BE12: Biometric | BF12: Logistics head | BG12: No | BH12: N/A | BI12: N/A | BJ12: N/A | BK12: N/A | BL12: Not applicable | BM12: N/A | BN12: N/A | BO12: N/A | BP12: Not applicable | BQ12: Not applicable
A13: EMP-011 | B13: Steelstone Building Materials (Pvt) Ltd | C13: Staff | D13: Irfan Ali | E13: Pakistani - no passport | F13: 34312 | G13: =DATEDIF(F13,TODAY(),"Y") -> 32 | H13: Male | I13: Married | J13: Islam | K13: B- | L13: Attached (EMP-011.jpg) | M13: 0345-6600808 | N13: N/A | O13: House 90, Street 8, Shadbagh, Lahore | P13: Same as present | Q13: Lahore / Punjab | R13: Nasreen - Wife | S13: 0327-8563322 | T13: Spouse / parent (as per emergency contact) | U13: 2 children - Ahmed (son, 2012), Hamza (son, 2018) | V13: 45644 | W13: Dispatch Officer | X13: Logistics | Y13: S-4 | Z13: Confirmed | AA13: 3 months - confirmation due Q1 2025 | AB13: N/A | AC13: N/A | AD13: =IF(ISNUMBER(AC13),IF(AC13<TODAY(),"Expired",IF(AC13-TODAY()<=30,"Expiring soon","Active")),"Not applicable") -> Not applicable | AE13: Bachelor's | AF13: BA | AG13: PU Lahore, 2015 | AH13: N/A | AI13: 9 | AJ13: Maple Leaf Cement - Executive - 4 yrs | AK13: 45654 | AL13: 3856465-2 | AM13: Active (ATL) | AN13: EOBI-165885197 | AO13: 45654 | AP13: Verified - Jan-2024 | AQ13: =IF(AND(LEFT(AP13,8)="Verified",AN13<>"Pending"),"Compliant","Non-compliant") -> Compliant | AR13: 90000 | AS13: =ROUND(AR13*0.6,0) -> 54000 | AT13: =ROUND(AS13*0.45,0) -> 24300 | AU13: Monthly withholding u/s 149 (below taxable limit) | AV13: Employee 1% / Employer 5% of minimum wage | AW13: Habib Bank Ltd | AX13: Irfan Ali | AY13: 4889-67161026-05 | AZ13: 14 | BA13: 10 | BB13: 8 | BC13: Calendar year (Jan-Dec) | BD13: 8 | BE13: Biometric | BF13: Logistics head | BG13: No | BH13: N/A | BI13: N/A | BJ13: N/A | BK13: N/A | BL13: Not applicable | BM13: N/A | BN13: N/A | BO13: N/A | BP13: Not applicable | BQ13: Not applicable
A14: EMP-012 | B14: Steelstone Building Materials (Pvt) Ltd | C14: Staff | D14: Shakeel Ahmed | E14: Pakistani - no passport | F14: 33935 | G14: =DATEDIF(F14,TODAY(),"Y") -> 33 | H14: Male | I14: Married | J14: Islam | K14: O+ | L14: Attached (EMP-012.jpg) | M14: 0349-6837070 | N14: N/A | O14: House 183, Street 19, Samanabad, Lahore | P14: Village Chak 45, Okara | Q14: Mardan / KP | R14: Rukhsana - Wife | S14: 0332-3449947 | T14: Spouse / parent (as per emergency contact) | U14: 2 children - Ahmed (son, 2012), Fatima (daughter, 2019) | V14: 45817 | W14: Warehouse In-charge | X14: Warehouse | Y14: S-3 | Z14: Confirmed | AA14: 3 months - confirmation due within 2025 | AB14: N/A | AC14: N/A | AD14: =IF(ISNUMBER(AC14),IF(AC14<TODAY(),"Expired",IF(AC14-TODAY()<=30,"Expiring soon","Active")),"Not applicable") -> Not applicable | AE14: Intermediate | AF14: FA | AG14: BISE Lahore, 2009 | AH14: N/A | AI14: 10 | AJ14: DG Khan Cement - Officer - 2 yrs | AK14: 45836 | AL14: 7801280-0 | AM14: Active (ATL) | AN14: EOBI-842560846 | AO14: 45836 | AP14: Verified - Mar-2025 | AQ14: =IF(AND(LEFT(AP14,8)="Verified",AN14<>"Pending"),"Compliant","Non-compliant") -> Compliant | AR14: 95000 | AS14: =ROUND(AR14*0.6,0) -> 57000 | AT14: =ROUND(AS14*0.45,0) -> 25650 | AU14: Monthly withholding u/s 149 (below taxable limit) | AV14: Employee 1% / Employer 5% of minimum wage | AW14: MCB Bank Ltd | AX14: Shakeel Ahmed | AY14: 7915-95834267-01 | AZ14: 14 | BA14: 10 | BB14: 8 | BC14: Calendar year (Jan-Dec) | BD14: 1 | BE14: Biometric | BF14: Warehouse head | BG14: No | BH14: N/A | BI14: N/A | BJ14: N/A | BK14: N/A | BL14: Not applicable | BM14: N/A | BN14: N/A | BO14: N/A | BP14: Not applicable | BQ14: Not applicable
A15: EMP-013 | B15: Steelstone Building Materials (Pvt) Ltd | C15: Staff | D15: Babar Hussain | E15: Pakistani - Passport BK3488707 | F15: 36731 | G15: =DATEDIF(F15,TODAY(),"Y") -> 26 | H15: Male | I15: Married | J15: Islam | K15: B- | L15: Attached (EMP-013.jpg) | M15: 0301-6550767 | N15: 0330-3587710 | O15: House 183, Street 24, Wapda Town, Lahore | P15: Same as present | Q15: Lahore / Punjab | R15: Nasreen - Wife | S15: 0349-6565210 | T15: Spouse / parent (as per emergency contact) | U15: None | V15: 45586 | W15: Storekeeper | X15: Warehouse | Y15: S-5 | Z15: Confirmed | AA15: 3 months - confirmation due Q1 2025 | AB15: N/A | AC15: N/A | AD15: =IF(ISNUMBER(AC15),IF(AC15<TODAY(),"Expired",IF(AC15-TODAY()<=30,"Expiring soon","Active")),"Not applicable") -> Not applicable | AE15: Matric | AF15: SSC | AG15: BISE Lahore, 2011 | AH15: N/A | AI15: 2 | AJ15: Lucky Cement - Officer - 3 yrs | AK15: 45593 | AL15: 9003000-1 | AM15: Active (ATL) | AN15: EOBI-409497664 | AO15: 45593 | AP15: Verified - May-2024 | AQ15: =IF(AND(LEFT(AP15,8)="Verified",AN15<>"Pending"),"Compliant","Non-compliant") -> Compliant | AR15: 60000 | AS15: =ROUND(AR15*0.6,0) -> 36000 | AT15: =ROUND(AS15*0.45,0) -> 16200 | AU15: Monthly withholding u/s 149 (below taxable limit) | AV15: Employee 1% / Employer 5% of minimum wage | AW15: MCB Bank Ltd | AX15: Babar Hussain | AY15: 4789-51762875-09 | AZ15: 14 | BA15: 10 | BB15: 8 | BC15: Calendar year (Jan-Dec) | BD15: 7 | BE15: Biometric | BF15: Warehouse head | BG15: No | BH15: N/A | BI15: N/A | BJ15: N/A | BK15: N/A | BL15: Not applicable | BM15: N/A | BN15: N/A | BO15: N/A | BP15: Not applicable | BQ15: Not applicable
A16: EMP-014 | B16: Steelstone Building Materials (Pvt) Ltd | C16: Staff | D16: Hina Aslam | E16: Pakistani - no passport | F16: 34005 | G16: =DATEDIF(F16,TODAY(),"Y") -> 33 | H16: Female | I16: Married | J16: Islam | K16: B+ | L16: Attached (EMP-014.jpg) | M16: 0343-9962805 | N16: N/A | O16: House 244, Street 4, Shadbagh, Lahore | P16: Same as present | Q16: Lahore / Punjab | R16: Asad - Husband | S16: 0305-8369126 | T16: Spouse / parent (as per emergency contact) | U16: 2 children - Ahmed (son, 2012), Hamza (son, 2018) | V16: 45840 | W16: HR & Admin Officer | X16: HR & Admin | Y16: S-2 | Z16: Confirmed | AA16: 3 months - confirmation due within 2025 | AB16: N/A | AC16: N/A | AD16: =IF(ISNUMBER(AC16),IF(AC16<TODAY(),"Expired",IF(AC16-TODAY()<=30,"Expiring soon","Active")),"Not applicable") -> Not applicable | AE16: Master's | AF16: MBA (HRM) | AG16: UMT Lahore, 2017 | AH16: N/A | AI16: 9 | AJ16: DG Khan Cement - Officer - 2 yrs | AK16: 45866 | AL16: 4921471-1 | AM16: Active (ATL) | AN16: EOBI-849528081 | AO16: 45866 | AP16: Verified - Aug-2025 | AQ16: =IF(AND(LEFT(AP16,8)="Verified",AN16<>"Pending"),"Compliant","Non-compliant") -> Compliant | AR16: 140000 | AS16: =ROUND(AR16*0.6,0) -> 84000 | AT16: =ROUND(AS16*0.45,0) -> 37800 | AU16: Monthly withholding u/s 149 (annualised) | AV16: Employee 1% / Employer 5% of minimum wage | AW16: Meezan Bank Ltd | AX16: Hina Aslam | AY16: 9214-74799196-09 | AZ16: 14 | BA16: 10 | BB16: 8 | BC16: Calendar year (Jan-Dec) | BD16: 4 | BE16: Biometric | BF16: HR & Admin head | BG16: No | BH16: N/A | BI16: N/A | BJ16: N/A | BK16: N/A | BL16: Not applicable | BM16: N/A | BN16: N/A | BO16: N/A | BP16: Not applicable | BQ16: Not applicable
A17: EMP-015 | B17: Steelstone Building Materials (Pvt) Ltd | C17: Staff | D17: Fahad Saleem | E17: Pakistani - no passport | F17: 35539 | G17: =DATEDIF(F17,TODAY(),"Y") -> 29 | H17: Male | I17: Single | J17: Islam | K17: A+ | L17: Attached (EMP-015.jpg) | M17: 0300-1526664 | N17: N/A | O17: House 233, Street 4, Township, Lahore | P17: Village Mouza Kot, Mardan | Q17: Lahore / Punjab | R17: Rukhsana - Mother | S17: 0336-8765253 | T17: Spouse / parent (as per emergency contact) | U17: None | V17: 45632 | W17: IT Officer | X17: IT | Y17: S-2 | Z17: Contract | AA17: 3 months - confirmation due Q1 2025 | AB17: 45627 | AC17: 46448 | AD17: =IF(ISNUMBER(AC17),IF(AC17<TODAY(),"Expired",IF(AC17-TODAY()<=30,"Expiring soon","Active")),"Not applicable") -> Active | AE17: Bachelor's | AF17: BS Computer Science | AG17: FAST Lahore, 2018 | AH17: N/A | AI17: 5 | AJ17: DG Khan Cement - Officer - 2 yrs | AK17: 45654 | AL17: Not registered | AM17: Non-filer | AN17: EOBI-463790851 | AO17: 45654 | AP17: Verified - Nov-2024 | AQ17: =IF(AND(LEFT(AP17,8)="Verified",AN17<>"Pending"),"Compliant","Non-compliant") -> Compliant | AR17: 150000 | AS17: =ROUND(AR17*0.6,0) -> 90000 | AT17: =ROUND(AS17*0.45,0) -> 40500 | AU17: Monthly withholding u/s 149 (annualised) | AV17: Employee 1% / Employer 5% of minimum wage | AW17: Habib Bank Ltd | AX17: Fahad Saleem | AY17: 4660-59580478-08 | AZ17: 14 | BA17: 10 | BB17: 8 | BC17: Calendar year (Jan-Dec) | BD17: 11 | BE17: Biometric | BF17: IT head | BG17: No | BH17: N/A | BI17: N/A | BJ17: N/A | BK17: N/A | BL17: Not applicable | BM17: N/A | BN17: N/A | BO17: N/A | BP17: Not applicable | BQ17: Not applicable
A18: EMP-016 | B18: Steelstone Building Materials (Pvt) Ltd | C18: Staff | D18: Ghulam Mustafa | E18: Pakistani - Passport DR7654514 | F18: 31753 | G18: =DATEDIF(F18,TODAY(),"Y") -> 39 | H18: Male | I18: Married | J18: Islam | K18: O- | L18: Attached (EMP-016.jpg) | M18: 0347-6110003 | N18: N/A | O18: House 292, Street 27, Township, Lahore | P18: Same as present | Q18: Lahore / Punjab | R18: Nasreen - Wife | S18: 0337-7227018 | T18: Spouse / parent (as per emergency contact) | U18: 2 children - Ayesha (daughter, 2015), Hamza (son, 2018) | V18: 45786 | W18: Security Supervisor | X18: HR & Admin | Y18: S-5 | Z18: Confirmed | AA18: 3 months - confirmation due within 2025 | AB18: N/A | AC18: N/A | AD18: =IF(ISNUMBER(AC18),IF(AC18<TODAY(),"Expired",IF(AC18-TODAY()<=30,"Expiring soon","Active")),"Not applicable") -> Not applicable | AE18: Matric | AF18: SSC + Ex-Army | AG18: BISE Rawalpindi, 1998 | AH18: N/A | AI18: 16 | AJ18: Fresh graduate | AK18: 45805 | AL18: 6045415-0 | AM18: Active (ATL) | AN18: EOBI-596396425 | AO18: 45805 | AP18: Verified - Jan-2025 | AQ18: =IF(AND(LEFT(AP18,8)="Verified",AN18<>"Pending"),"Compliant","Non-compliant") -> Compliant | AR18: 55000 | AS18: =ROUND(AR18*0.6,0) -> 33000 | AT18: =ROUND(AS18*0.45,0) -> 14850 | AU18: Monthly withholding u/s 149 (below taxable limit) | AV18: Employee 1% / Employer 5% of minimum wage | AW18: MCB Bank Ltd | AX18: Ghulam Mustafa | AY18: 1102-95724997-07 | AZ18: 14 | BA18: 10 | BB18: 8 | BC18: Calendar year (Jan-Dec) | BD18: 3 | BE18: Biometric | BF18: HR & Admin head | BG18: No | BH18: N/A | BI18: N/A | BJ18: N/A | BK18: N/A | BL18: Not applicable | BM18: N/A | BN18: N/A | BO18: N/A | BP18: Not applicable | BQ18: Not applicable
